2019-02-24 15:10:31,501 ERROR: Exception on /logout [GET] [in c:\users\celia\microblog\venv\lib\site-packages\flask\app.py:1761]
Traceback (most recent call last):
  File "c:\users\celia\microblog\venv\lib\site-packages\flask\app.py", line 2292, in wsgi_app
    response = self.full_dispatch_request()
  File "c:\users\celia\microblog\venv\lib\site-packages\flask\app.py", line 1815, in full_dispatch_request
    rv = self.handle_user_exception(e)
  File "c:\users\celia\microblog\venv\lib\site-packages\flask\app.py", line 1718, in handle_user_exception
    reraise(exc_type, exc_value, tb)
  File "c:\users\celia\microblog\venv\lib\site-packages\flask\_compat.py", line 35, in reraise
    raise value
  File "c:\users\celia\microblog\venv\lib\site-packages\flask\app.py", line 1811, in full_dispatch_request
    rv = self.preprocess_request()
  File "c:\users\celia\microblog\venv\lib\site-packages\flask\app.py", line 2087, in preprocess_request
    rv = func()
  File "C:\Users\celia\microblog\app\routes.py", line 87, in before_request
    if current_user.is_authenticated:
  File "c:\users\celia\microblog\venv\lib\site-packages\werkzeug\local.py", line 347, in __getattr__
    return getattr(self._get_current_object(), name)
AttributeError: 'User' object has no attribute 'is_authenticated'
2019-02-24 15:39:11,742 INFO: PIA Chatbot startup [in C:\Users\celia\microblog\app\__init__.py:44]
2019-02-24 15:39:27,872 ERROR: Exception on /logout [GET] [in c:\users\celia\microblog\venv\lib\site-packages\flask\app.py:1761]
Traceback (most recent call last):
  File "c:\users\celia\microblog\venv\lib\site-packages\flask\app.py", line 2292, in wsgi_app
    response = self.full_dispatch_request()
  File "c:\users\celia\microblog\venv\lib\site-packages\flask\app.py", line 1815, in full_dispatch_request
    rv = self.handle_user_exception(e)
  File "c:\users\celia\microblog\venv\lib\site-packages\flask\app.py", line 1718, in handle_user_exception
    reraise(exc_type, exc_value, tb)
  File "c:\users\celia\microblog\venv\lib\site-packages\flask\_compat.py", line 35, in reraise
    raise value
  File "c:\users\celia\microblog\venv\lib\site-packages\flask\app.py", line 1811, in full_dispatch_request
    rv = self.preprocess_request()
  File "c:\users\celia\microblog\venv\lib\site-packages\flask\app.py", line 2087, in preprocess_request
    rv = func()
  File "C:\Users\celia\microblog\app\routes.py", line 87, in before_request
    if current_user.is_authenticated:
  File "c:\users\celia\microblog\venv\lib\site-packages\werkzeug\local.py", line 347, in __getattr__
    return getattr(self._get_current_object(), name)
AttributeError: 'User' object has no attribute 'is_authenticated'
2019-02-24 15:39:50,308 ERROR: Exception on /user/Célia [GET] [in c:\users\celia\microblog\venv\lib\site-packages\flask\app.py:1761]
Traceback (most recent call last):
  File "c:\users\celia\microblog\venv\lib\site-packages\flask\app.py", line 2292, in wsgi_app
    response = self.full_dispatch_request()
  File "c:\users\celia\microblog\venv\lib\site-packages\flask\app.py", line 1815, in full_dispatch_request
    rv = self.handle_user_exception(e)
  File "c:\users\celia\microblog\venv\lib\site-packages\flask\app.py", line 1718, in handle_user_exception
    reraise(exc_type, exc_value, tb)
  File "c:\users\celia\microblog\venv\lib\site-packages\flask\_compat.py", line 35, in reraise
    raise value
  File "c:\users\celia\microblog\venv\lib\site-packages\flask\app.py", line 1811, in full_dispatch_request
    rv = self.preprocess_request()
  File "c:\users\celia\microblog\venv\lib\site-packages\flask\app.py", line 2087, in preprocess_request
    rv = func()
  File "C:\Users\celia\microblog\app\routes.py", line 87, in before_request
    if current_user.is_authenticated:
  File "c:\users\celia\microblog\venv\lib\site-packages\werkzeug\local.py", line 347, in __getattr__
    return getattr(self._get_current_object(), name)
AttributeError: 'User' object has no attribute 'is_authenticated'
2019-02-24 15:40:06,728 INFO: PIA Chatbot startup [in C:\Users\celia\microblog\app\__init__.py:44]
2019-02-24 15:40:16,097 ERROR: Exception on /user/Célia [GET] [in c:\users\celia\microblog\venv\lib\site-packages\flask\app.py:1761]
Traceback (most recent call last):
  File "c:\users\celia\microblog\venv\lib\site-packages\flask\app.py", line 2292, in wsgi_app
    response = self.full_dispatch_request()
  File "c:\users\celia\microblog\venv\lib\site-packages\flask\app.py", line 1815, in full_dispatch_request
    rv = self.handle_user_exception(e)
  File "c:\users\celia\microblog\venv\lib\site-packages\flask\app.py", line 1718, in handle_user_exception
    reraise(exc_type, exc_value, tb)
  File "c:\users\celia\microblog\venv\lib\site-packages\flask\_compat.py", line 35, in reraise
    raise value
  File "c:\users\celia\microblog\venv\lib\site-packages\flask\app.py", line 1811, in full_dispatch_request
    rv = self.preprocess_request()
  File "c:\users\celia\microblog\venv\lib\site-packages\flask\app.py", line 2087, in preprocess_request
    rv = func()
  File "C:\Users\celia\microblog\app\routes.py", line 87, in before_request
    if current_user.is_authenticated:
  File "c:\users\celia\microblog\venv\lib\site-packages\werkzeug\local.py", line 347, in __getattr__
    return getattr(self._get_current_object(), name)
AttributeError: 'User' object has no attribute 'is_authenticated'
2019-02-24 16:24:04,263 INFO: PIA Chatbot startup [in C:\Users\celia\microblog\app\__init__.py:46]
2019-02-24 16:37:26,167 ERROR: Exception on /reset_password_request [POST] [in c:\users\celia\microblog\venv\lib\site-packages\flask\app.py:1761]
Traceback (most recent call last):
  File "c:\users\celia\microblog\venv\lib\site-packages\flask\app.py", line 2292, in wsgi_app
    response = self.full_dispatch_request()
  File "c:\users\celia\microblog\venv\lib\site-packages\flask\app.py", line 1815, in full_dispatch_request
    rv = self.handle_user_exception(e)
  File "c:\users\celia\microblog\venv\lib\site-packages\flask\app.py", line 1718, in handle_user_exception
    reraise(exc_type, exc_value, tb)
  File "c:\users\celia\microblog\venv\lib\site-packages\flask\_compat.py", line 35, in reraise
    raise value
  File "c:\users\celia\microblog\venv\lib\site-packages\flask\app.py", line 1813, in full_dispatch_request
    rv = self.dispatch_request()
  File "c:\users\celia\microblog\venv\lib\site-packages\flask\app.py", line 1799, in dispatch_request
    return self.view_functions[rule.endpoint](**req.view_args)
  File "C:\Users\celia\microblog\app\routes.py", line 102, in reset_password_request
    send_password_reset_email(user)
  File "C:\Users\celia\microblog\app\email.py", line 14, in send_password_reset_email
    sender=app.config['ADMINS'][0],
NameError: name 'app' is not defined
2019-02-24 16:39:36,318 ERROR: Exception on /reset_password_request [POST] [in c:\users\celia\microblog\venv\lib\site-packages\flask\app.py:1761]
Traceback (most recent call last):
  File "c:\users\celia\microblog\venv\lib\site-packages\flask\app.py", line 2292, in wsgi_app
    response = self.full_dispatch_request()
  File "c:\users\celia\microblog\venv\lib\site-packages\flask\app.py", line 1815, in full_dispatch_request
    rv = self.handle_user_exception(e)
  File "c:\users\celia\microblog\venv\lib\site-packages\flask\app.py", line 1718, in handle_user_exception
    reraise(exc_type, exc_value, tb)
  File "c:\users\celia\microblog\venv\lib\site-packages\flask\_compat.py", line 35, in reraise
    raise value
  File "c:\users\celia\microblog\venv\lib\site-packages\flask\app.py", line 1813, in full_dispatch_request
    rv = self.dispatch_request()
  File "c:\users\celia\microblog\venv\lib\site-packages\flask\app.py", line 1799, in dispatch_request
    return self.view_functions[rule.endpoint](**req.view_args)
  File "C:\Users\celia\microblog\app\routes.py", line 102, in reset_password_request
    send_password_reset_email(user)
  File "C:\Users\celia\microblog\app\email.py", line 14, in send_password_reset_email
    sender=app.config['ADMINS'][0],
NameError: name 'app' is not defined
2019-02-24 16:39:49,502 INFO: PIA Chatbot startup [in C:\Users\celia\microblog\app\__init__.py:46]
2019-02-24 16:39:56,878 ERROR: Exception on /reset_password_request [POST] [in c:\users\celia\microblog\venv\lib\site-packages\flask\app.py:1761]
Traceback (most recent call last):
  File "c:\users\celia\microblog\venv\lib\site-packages\flask\app.py", line 2292, in wsgi_app
    response = self.full_dispatch_request()
  File "c:\users\celia\microblog\venv\lib\site-packages\flask\app.py", line 1815, in full_dispatch_request
    rv = self.handle_user_exception(e)
  File "c:\users\celia\microblog\venv\lib\site-packages\flask\app.py", line 1718, in handle_user_exception
    reraise(exc_type, exc_value, tb)
  File "c:\users\celia\microblog\venv\lib\site-packages\flask\_compat.py", line 35, in reraise
    raise value
  File "c:\users\celia\microblog\venv\lib\site-packages\flask\app.py", line 1813, in full_dispatch_request
    rv = self.dispatch_request()
  File "c:\users\celia\microblog\venv\lib\site-packages\flask\app.py", line 1799, in dispatch_request
    return self.view_functions[rule.endpoint](**req.view_args)
  File "C:\Users\celia\microblog\app\routes.py", line 102, in reset_password_request
    send_password_reset_email(user)
  File "C:\Users\celia\microblog\app\email.py", line 16, in send_password_reset_email
    text_body=render_template('email/reset_password.txt',
NameError: name 'render_template' is not defined
2019-02-24 16:40:33,604 INFO: PIA Chatbot startup [in C:\Users\celia\microblog\app\__init__.py:46]
