2019-02-25 09:23:53,173 ERROR: Exception on /reset_password_request [POST] [in c:\users\celia\microblog\venv\lib\site-packages\flask\app.py:1761]
Traceback (most recent call last):
  File "c:\users\celia\microblog\venv\lib\site-packages\flask\app.py", line 2292, in wsgi_app
    response = self.full_dispatch_request()
  File "c:\users\celia\microblog\venv\lib\site-packages\flask\app.py", line 1815, in full_dispatch_request
    rv = self.handle_user_exception(e)
  File "c:\users\celia\microblog\venv\lib\site-packages\flask\app.py", line 1718, in handle_user_exception
    reraise(exc_type, exc_value, tb)
  File "c:\users\celia\microblog\venv\lib\site-packages\flask\_compat.py", line 35, in reraise
    raise value
  File "c:\users\celia\microblog\venv\lib\site-packages\flask\app.py", line 1813, in full_dispatch_request
    rv = self.dispatch_request()
  File "c:\users\celia\microblog\venv\lib\site-packages\flask\app.py", line 1799, in dispatch_request
    return self.view_functions[rule.endpoint](**req.view_args)
  File "C:\Users\celia\microblog\app\routes.py", line 113, in reset_password_request
    send_password_reset_email(user)
  File "C:\Users\celia\microblog\app\email.py", line 26, in send_password_reset_email
    user=user, token=token),
  File "c:\users\celia\microblog\venv\lib\site-packages\flask\templating.py", line 134, in render_template
    return _render(ctx.app.jinja_env.get_or_select_template(template_name_or_list),
  File "c:\users\celia\microblog\venv\lib\site-packages\jinja2\environment.py", line 869, in get_or_select_template
    return self.get_template(template_name_or_list, parent, globals)
  File "c:\users\celia\microblog\venv\lib\site-packages\jinja2\environment.py", line 830, in get_template
    return self._load_template(name, self.make_globals(globals))
  File "c:\users\celia\microblog\venv\lib\site-packages\jinja2\environment.py", line 804, in _load_template
    template = self.loader.load(self, name, globals)
  File "c:\users\celia\microblog\venv\lib\site-packages\jinja2\loaders.py", line 113, in load
    source, filename, uptodate = self.get_source(environment, name)
  File "c:\users\celia\microblog\venv\lib\site-packages\flask\templating.py", line 58, in get_source
    return self._get_source_fast(environment, template)
  File "c:\users\celia\microblog\venv\lib\site-packages\flask\templating.py", line 83, in _get_source_fast
    return loader.get_source(environment, template)
  File "c:\users\celia\microblog\venv\lib\site-packages\jinja2\loaders.py", line 175, in get_source
    contents = f.read().decode(self.encoding)
UnicodeDecodeError: 'utf-8' codec can't decode byte 0xe9 in position 43: invalid continuation byte
2019-02-26 09:17:10,573 INFO: Microblog startup [in C:\Users\celia\microblog\app\__init__.py:53]
2019-02-26 09:21:58,090 INFO: Microblog startup [in C:\Users\celia\microblog\app\__init__.py:53]
2019-02-26 09:23:58,456 INFO: Microblog startup [in C:\Users\celia\microblog\app\__init__.py:53]
2019-02-26 09:24:06,367 INFO: Microblog startup [in C:\Users\celia\microblog\app\__init__.py:53]
2019-02-26 09:25:42,959 INFO: Microblog startup [in C:\Users\celia\microblog\app\__init__.py:53]
2019-02-26 09:27:30,115 INFO: Microblog startup [in C:\Users\celia\microblog\app\__init__.py:53]
2019-02-26 09:31:50,706 INFO: Microblog startup [in C:\Users\celia\microblog\app\__init__.py:53]
2019-02-26 09:32:21,068 INFO: Microblog startup [in C:\Users\celia\microblog\app\__init__.py:53]
2019-02-26 09:32:40,340 INFO: Microblog startup [in C:\Users\celia\microblog\app\__init__.py:53]
2019-02-26 09:34:02,431 INFO: Microblog startup [in C:\Users\celia\microblog\app\__init__.py:53]
2019-02-26 09:38:29,569 INFO: Microblog startup [in C:\Users\celia\microblog\app\__init__.py:53]
2019-02-26 10:14:54,749 INFO: Microblog startup [in C:\Users\celia\microblog\app\__init__.py:74]
