2019-02-24 12:35:34,658 ERROR: Exception on /index [GET] [in c:\users\celia\microblog\venv\lib\site-packages\flask\app.py:1761]
Traceback (most recent call last):
  File "c:\users\celia\microblog\venv\lib\site-packages\flask\app.py", line 2292, in wsgi_app
    response = self.full_dispatch_request()
  File "c:\users\celia\microblog\venv\lib\site-packages\flask\app.py", line 1815, in full_dispatch_request
    rv = self.handle_user_exception(e)
  File "c:\users\celia\microblog\venv\lib\site-packages\flask\app.py", line 1718, in handle_user_exception
    reraise(exc_type, exc_value, tb)
  File "c:\users\celia\microblog\venv\lib\site-packages\flask\_compat.py", line 35, in reraise
    raise value
  File "c:\users\celia\microblog\venv\lib\site-packages\flask\app.py", line 1813, in full_dispatch_request
    rv = self.dispatch_request()
  File "c:\users\celia\microblog\venv\lib\site-packages\flask\app.py", line 1799, in dispatch_request
    return self.view_functions[rule.endpoint](**req.view_args)
TypeError: index() missing 1 required positional argument: 'username'
2019-02-24 12:38:55,551 INFO: PIA Chatbot startup [in C:\Users\celia\microblog\app\__init__.py:42]
2019-02-24 12:38:58,207 ERROR: Exception on /index [GET] [in c:\users\celia\microblog\venv\lib\site-packages\flask\app.py:1761]
Traceback (most recent call last):
  File "c:\users\celia\microblog\venv\lib\site-packages\flask\app.py", line 2292, in wsgi_app
    response = self.full_dispatch_request()
  File "c:\users\celia\microblog\venv\lib\site-packages\flask\app.py", line 1815, in full_dispatch_request
    rv = self.handle_user_exception(e)
  File "c:\users\celia\microblog\venv\lib\site-packages\flask\app.py", line 1718, in handle_user_exception
    reraise(exc_type, exc_value, tb)
  File "c:\users\celia\microblog\venv\lib\site-packages\flask\_compat.py", line 35, in reraise
    raise value
  File "c:\users\celia\microblog\venv\lib\site-packages\flask\app.py", line 1813, in full_dispatch_request
    rv = self.dispatch_request()
  File "c:\users\celia\microblog\venv\lib\site-packages\flask\app.py", line 1799, in dispatch_request
    return self.view_functions[rule.endpoint](**req.view_args)
TypeError: index() missing 1 required positional argument: 'username'
2019-02-24 12:40:02,857 INFO: PIA Chatbot startup [in C:\Users\celia\microblog\app\__init__.py:42]
2019-02-24 12:40:56,220 INFO: PIA Chatbot startup [in C:\Users\celia\microblog\app\__init__.py:42]
2019-02-24 12:41:35,706 INFO: PIA Chatbot startup [in C:\Users\celia\microblog\app\__init__.py:42]
2019-02-24 12:42:20,759 INFO: PIA Chatbot startup [in C:\Users\celia\microblog\app\__init__.py:42]
2019-02-24 12:44:52,021 INFO: PIA Chatbot startup [in C:\Users\celia\microblog\app\__init__.py:42]
2019-02-24 12:48:46,238 INFO: PIA Chatbot startup [in C:\Users\celia\microblog\app\__init__.py:42]
2019-02-24 12:50:33,616 INFO: PIA Chatbot startup [in C:\Users\celia\microblog\app\__init__.py:42]
2019-02-24 12:52:29,850 INFO: PIA Chatbot startup [in C:\Users\celia\microblog\app\__init__.py:42]
2019-02-24 12:56:37,228 INFO: PIA Chatbot startup [in C:\Users\celia\microblog\app\__init__.py:42]
2019-02-24 12:56:41,715 ERROR: Exception on /index [GET] [in c:\users\celia\microblog\venv\lib\site-packages\flask\app.py:1761]
Traceback (most recent call last):
  File "c:\users\celia\microblog\venv\lib\site-packages\flask\app.py", line 2292, in wsgi_app
    response = self.full_dispatch_request()
  File "c:\users\celia\microblog\venv\lib\site-packages\flask\app.py", line 1815, in full_dispatch_request
    rv = self.handle_user_exception(e)
  File "c:\users\celia\microblog\venv\lib\site-packages\flask\app.py", line 1718, in handle_user_exception
    reraise(exc_type, exc_value, tb)
  File "c:\users\celia\microblog\venv\lib\site-packages\flask\_compat.py", line 35, in reraise
    raise value
  File "c:\users\celia\microblog\venv\lib\site-packages\flask\app.py", line 1813, in full_dispatch_request
    rv = self.dispatch_request()
  File "c:\users\celia\microblog\venv\lib\site-packages\flask\app.py", line 1799, in dispatch_request
    return self.view_functions[rule.endpoint](**req.view_args)
  File "C:\Users\celia\microblog\app\routes.py", line 24, in index
    return render_template('index.html', title='Home', user=user, posts=posts)
  File "c:\users\celia\microblog\venv\lib\site-packages\flask\templating.py", line 135, in render_template
    context, ctx.app)
  File "c:\users\celia\microblog\venv\lib\site-packages\flask\templating.py", line 117, in _render
    rv = template.render(context)
  File "c:\users\celia\microblog\venv\lib\site-packages\jinja2\asyncsupport.py", line 76, in render
    return original_render(self, *args, **kwargs)
  File "c:\users\celia\microblog\venv\lib\site-packages\jinja2\environment.py", line 1008, in render
    return self.environment.handle_exception(exc_info, True)
  File "c:\users\celia\microblog\venv\lib\site-packages\jinja2\environment.py", line 780, in handle_exception
    reraise(exc_type, exc_value, tb)
  File "c:\users\celia\microblog\venv\lib\site-packages\jinja2\_compat.py", line 37, in reraise
    raise value.with_traceback(tb)
  File "C:\Users\celia\microblog\app\templates\index.html", line 1, in top-level template code
    {% extends "base.html" %}
  File "C:\Users\celia\microblog\app\templates\base.html", line 26, in top-level template code
    {% block content %}{% endblock %}
  File "C:\Users\celia\microblog\app\templates\index.html", line 6, in block "content"
    {{ form.hidden_tag() }}
  File "c:\users\celia\microblog\venv\lib\site-packages\jinja2\environment.py", line 430, in getattr
    return getattr(obj, attribute)
jinja2.exceptions.UndefinedError: 'form' is undefined
2019-02-24 13:04:13,348 INFO: PIA Chatbot startup [in C:\Users\celia\microblog\app\__init__.py:42]
2019-02-24 13:04:16,884 ERROR: Exception on /index [GET] [in c:\users\celia\microblog\venv\lib\site-packages\flask\app.py:1761]
Traceback (most recent call last):
  File "c:\users\celia\microblog\venv\lib\site-packages\flask\app.py", line 2292, in wsgi_app
    response = self.full_dispatch_request()
  File "c:\users\celia\microblog\venv\lib\site-packages\flask\app.py", line 1815, in full_dispatch_request
    rv = self.handle_user_exception(e)
  File "c:\users\celia\microblog\venv\lib\site-packages\flask\app.py", line 1718, in handle_user_exception
    reraise(exc_type, exc_value, tb)
  File "c:\users\celia\microblog\venv\lib\site-packages\flask\_compat.py", line 35, in reraise
    raise value
  File "c:\users\celia\microblog\venv\lib\site-packages\flask\app.py", line 1813, in full_dispatch_request
    rv = self.dispatch_request()
  File "c:\users\celia\microblog\venv\lib\site-packages\flask\app.py", line 1799, in dispatch_request
    return self.view_functions[rule.endpoint](**req.view_args)
  File "c:\users\celia\microblog\venv\lib\site-packages\flask_login\utils.py", line 261, in decorated_view
    return func(*args, **kwargs)
  File "C:\Users\celia\microblog\app\routes.py", line 29, in index
    posts = current_user.followed_posts().all()
  File "c:\users\celia\microblog\venv\lib\site-packages\werkzeug\local.py", line 347, in __getattr__
    return getattr(self._get_current_object(), name)
AttributeError: 'User' object has no attribute 'followed_posts'
2019-02-24 13:08:13,827 INFO: PIA Chatbot startup [in C:\Users\celia\microblog\app\__init__.py:42]
2019-02-24 13:08:22,214 INFO: PIA Chatbot startup [in C:\Users\celia\microblog\app\__init__.py:42]
2019-02-24 14:30:45,419 INFO: PIA Chatbot startup [in C:\Users\celia\microblog\app\__init__.py:42]
2019-02-24 14:30:50,702 ERROR: Exception on /index [GET] [in c:\users\celia\microblog\venv\lib\site-packages\flask\app.py:1761]
Traceback (most recent call last):
  File "c:\users\celia\microblog\venv\lib\site-packages\flask\app.py", line 2292, in wsgi_app
    response = self.full_dispatch_request()
  File "c:\users\celia\microblog\venv\lib\site-packages\flask\app.py", line 1815, in full_dispatch_request
    rv = self.handle_user_exception(e)
  File "c:\users\celia\microblog\venv\lib\site-packages\flask\app.py", line 1718, in handle_user_exception
    reraise(exc_type, exc_value, tb)
  File "c:\users\celia\microblog\venv\lib\site-packages\flask\_compat.py", line 35, in reraise
    raise value
  File "c:\users\celia\microblog\venv\lib\site-packages\flask\app.py", line 1813, in full_dispatch_request
    rv = self.dispatch_request()
  File "c:\users\celia\microblog\venv\lib\site-packages\flask\app.py", line 1799, in dispatch_request
    return self.view_functions[rule.endpoint](**req.view_args)
  File "c:\users\celia\microblog\venv\lib\site-packages\flask_login\utils.py", line 261, in decorated_view
    return func(*args, **kwargs)
  File "C:\Users\celia\microblog\app\routes.py", line 29, in index
    posts = current_user.followed_posts().all()
  File "c:\users\celia\microblog\venv\lib\site-packages\werkzeug\local.py", line 347, in __getattr__
    return getattr(self._get_current_object(), name)
AttributeError: 'User' object has no attribute 'followed_posts'
2019-02-24 14:35:28,172 INFO: PIA Chatbot startup [in C:\Users\celia\microblog\app\__init__.py:42]
2019-02-24 14:36:39,226 INFO: PIA Chatbot startup [in C:\Users\celia\microblog\app\__init__.py:42]
2019-02-24 14:40:01,417 INFO: PIA Chatbot startup [in C:\Users\celia\microblog\app\__init__.py:42]
