2019-02-26 17:30:13,731 ERROR: Exception on /index [POST] [in c:\users\celia\microblog\venv\lib\site-packages\flask\app.py:1761]
Traceback (most recent call last):
  File "c:\users\celia\microblog\venv\lib\site-packages\flask\app.py", line 2292, in wsgi_app
    response = self.full_dispatch_request()
  File "c:\users\celia\microblog\venv\lib\site-packages\flask\app.py", line 1816, in full_dispatch_request
    return self.finalize_request(rv)
  File "c:\users\celia\microblog\venv\lib\site-packages\flask\app.py", line 1833, in finalize_request
    response = self.process_response(response)
  File "c:\users\celia\microblog\venv\lib\site-packages\flask\app.py", line 2114, in process_response
    self.session_interface.save_session(self, ctx.session, response)
  File "c:\users\celia\microblog\venv\lib\site-packages\flask\sessions.py", line 375, in save_session
    val = self.get_signing_serializer(app).dumps(dict(session))
  File "c:\users\celia\microblog\venv\lib\site-packages\itsdangerous\serializer.py", line 166, in dumps
    payload = want_bytes(self.dump_payload(obj))
  File "c:\users\celia\microblog\venv\lib\site-packages\itsdangerous\url_safe.py", line 42, in dump_payload
    json = super(URLSafeSerializerMixin, self).dump_payload(obj)
  File "c:\users\celia\microblog\venv\lib\site-packages\itsdangerous\serializer.py", line 133, in dump_payload
    return want_bytes(self.serializer.dumps(obj, **self.serializer_kwargs))
  File "c:\users\celia\microblog\venv\lib\site-packages\flask\json\tag.py", line 296, in dumps
    return dumps(self.tag(value), separators=(',', ':'))
  File "c:\users\celia\microblog\venv\lib\site-packages\flask\json\__init__.py", line 179, in dumps
    rv = _json.dumps(obj, **kwargs)
  File "C:\Users\celia\Miniconda3\lib\json\__init__.py", line 238, in dumps
    **kw).encode(obj)
  File "C:\Users\celia\Miniconda3\lib\json\encoder.py", line 199, in encode
    chunks = self.iterencode(o, _one_shot=True)
  File "C:\Users\celia\Miniconda3\lib\json\encoder.py", line 257, in iterencode
    return _iterencode(o, 0)
  File "c:\users\celia\microblog\venv\lib\site-packages\flask\json\__init__.py", line 81, in default
    return _json.JSONEncoder.default(self, o)
  File "C:\Users\celia\Miniconda3\lib\json\encoder.py", line 179, in default
    raise TypeError(f'Object of type {o.__class__.__name__} '
TypeError: Object of type Post is not JSON serializable
2019-02-26 17:31:49,184 INFO: PIA Chatbot startup [in C:\Users\celia\microblog\app\__init__.py:74]
2019-02-26 17:44:49,925 INFO: PIA Chatbot startup [in C:\Users\celia\microblog\app\__init__.py:74]
2019-02-26 17:46:28,559 INFO: PIA Chatbot startup [in C:\Users\celia\microblog\app\__init__.py:74]
2019-02-26 17:46:53,304 INFO: PIA Chatbot startup [in C:\Users\celia\microblog\app\__init__.py:74]
2019-02-26 17:47:16,680 INFO: PIA Chatbot startup [in C:\Users\celia\microblog\app\__init__.py:74]
2019-02-26 17:49:22,400 INFO: PIA Chatbot startup [in C:\Users\celia\microblog\app\__init__.py:74]
2019-02-26 17:55:28,658 INFO: PIA Chatbot startup [in C:\Users\celia\microblog\app\__init__.py:74]
2019-02-26 17:58:54,974 INFO: PIA Chatbot startup [in C:\Users\celia\microblog\app\__init__.py:74]
2019-02-26 17:59:44,641 INFO: PIA Chatbot startup [in C:\Users\celia\microblog\app\__init__.py:74]
2019-02-26 18:00:40,218 INFO: PIA Chatbot startup [in C:\Users\celia\microblog\app\__init__.py:74]
2019-02-26 18:01:39,293 INFO: PIA Chatbot startup [in C:\Users\celia\microblog\app\__init__.py:74]
2019-02-26 18:02:58,232 INFO: PIA Chatbot startup [in C:\Users\celia\microblog\app\__init__.py:74]
2019-02-26 21:34:34,891 INFO: PIA Chatbot startup [in C:\Users\celia\microblog\app\__init__.py:74]
2019-02-26 21:40:04,402 INFO: PIA Chatbot startup [in C:\Users\celia\microblog\app\__init__.py:74]
2019-02-26 21:40:49,360 INFO: PIA Chatbot startup [in C:\Users\celia\microblog\app\__init__.py:74]
2019-02-26 21:42:34,261 INFO: PIA Chatbot startup [in C:\Users\celia\microblog\app\__init__.py:74]
2019-02-26 21:46:07,381 INFO: PIA Chatbot startup [in C:\Users\celia\microblog\app\__init__.py:74]
2019-02-26 21:55:50,556 INFO: PIA Chatbot startup [in C:\Users\celia\microblog\app\__init__.py:74]
2019-02-26 21:56:01,386 INFO: PIA Chatbot startup [in C:\Users\celia\microblog\app\__init__.py:74]
2019-02-26 21:59:29,490 INFO: PIA Chatbot startup [in C:\Users\celia\microblog\app\__init__.py:74]
2019-02-26 22:08:12,511 ERROR: Exception on /auth/reset_password_request [POST] [in c:\users\celia\microblog\venv\lib\site-packages\flask\app.py:1761]
Traceback (most recent call last):
  File "c:\users\celia\microblog\venv\lib\site-packages\flask\app.py", line 2292, in wsgi_app
    response = self.full_dispatch_request()
  File "c:\users\celia\microblog\venv\lib\site-packages\flask\app.py", line 1815, in full_dispatch_request
    rv = self.handle_user_exception(e)
  File "c:\users\celia\microblog\venv\lib\site-packages\flask\app.py", line 1718, in handle_user_exception
    reraise(exc_type, exc_value, tb)
  File "c:\users\celia\microblog\venv\lib\site-packages\flask\_compat.py", line 35, in reraise
    raise value
  File "c:\users\celia\microblog\venv\lib\site-packages\flask\app.py", line 1813, in full_dispatch_request
    rv = self.dispatch_request()
  File "c:\users\celia\microblog\venv\lib\site-packages\flask\app.py", line 1799, in dispatch_request
    return self.view_functions[rule.endpoint](**req.view_args)
  File "C:\Users\celia\microblog\app\auth\routes.py", line 61, in reset_password_request
    send_password_reset_email(user)
  File "C:\Users\celia\microblog\app\auth\email.py", line 12, in send_password_reset_email
    user=user, token=token),
  File "c:\users\celia\microblog\venv\lib\site-packages\flask\templating.py", line 134, in render_template
    return _render(ctx.app.jinja_env.get_or_select_template(template_name_or_list),
  File "c:\users\celia\microblog\venv\lib\site-packages\jinja2\environment.py", line 869, in get_or_select_template
    return self.get_template(template_name_or_list, parent, globals)
  File "c:\users\celia\microblog\venv\lib\site-packages\jinja2\environment.py", line 830, in get_template
    return self._load_template(name, self.make_globals(globals))
  File "c:\users\celia\microblog\venv\lib\site-packages\jinja2\environment.py", line 804, in _load_template
    template = self.loader.load(self, name, globals)
  File "c:\users\celia\microblog\venv\lib\site-packages\jinja2\loaders.py", line 113, in load
    source, filename, uptodate = self.get_source(environment, name)
  File "c:\users\celia\microblog\venv\lib\site-packages\flask\templating.py", line 58, in get_source
    return self._get_source_fast(environment, template)
  File "c:\users\celia\microblog\venv\lib\site-packages\flask\templating.py", line 83, in _get_source_fast
    return loader.get_source(environment, template)
  File "c:\users\celia\microblog\venv\lib\site-packages\jinja2\loaders.py", line 175, in get_source
    contents = f.read().decode(self.encoding)
UnicodeDecodeError: 'utf-8' codec can't decode byte 0xe9 in position 43: invalid continuation byte
2019-02-26 22:34:40,656 INFO: PIA Chatbot startup [in C:\Users\celia\microblog\app\__init__.py:74]
2019-02-26 22:39:14,600 INFO: PIA Chatbot startup [in C:\Users\celia\microblog\app\__init__.py:74]
2019-02-26 22:41:31,945 INFO: PIA Chatbot startup [in C:\Users\celia\microblog\app\__init__.py:74]
2019-02-26 22:45:26,178 INFO: PIA Chatbot startup [in C:\Users\celia\microblog\app\__init__.py:74]
2019-02-26 22:45:51,305 ERROR: Exception on /database [GET] [in c:\users\celia\microblog\venv\lib\site-packages\flask\app.py:1761]
Traceback (most recent call last):
  File "c:\users\celia\microblog\venv\lib\site-packages\flask\app.py", line 2292, in wsgi_app
    response = self.full_dispatch_request()
  File "c:\users\celia\microblog\venv\lib\site-packages\flask\app.py", line 1815, in full_dispatch_request
    rv = self.handle_user_exception(e)
  File "c:\users\celia\microblog\venv\lib\site-packages\flask\app.py", line 1718, in handle_user_exception
    reraise(exc_type, exc_value, tb)
  File "c:\users\celia\microblog\venv\lib\site-packages\flask\_compat.py", line 35, in reraise
    raise value
  File "c:\users\celia\microblog\venv\lib\site-packages\flask\app.py", line 1813, in full_dispatch_request
    rv = self.dispatch_request()
  File "c:\users\celia\microblog\venv\lib\site-packages\flask\app.py", line 1799, in dispatch_request
    return self.view_functions[rule.endpoint](**req.view_args)
  File "C:\Users\celia\microblog\app\main\routes.py", line 130, in display_database
    post = Post(body=form.post.data, author=current_user,language=language)
NameError: name 'language' is not defined
2019-02-26 22:46:42,735 INFO: PIA Chatbot startup [in C:\Users\celia\microblog\app\__init__.py:74]
