2019-03-02 11:15:50,940 ERROR: Exception on / [GET] [in c:\users\celia\microblog\venv\lib\site-packages\flask\app.py:1761]
Traceback (most recent call last):
  File "c:\users\celia\microblog\venv\lib\site-packages\flask\app.py", line 2292, in wsgi_app
    response = self.full_dispatch_request()
  File "c:\users\celia\microblog\venv\lib\site-packages\flask\app.py", line 1815, in full_dispatch_request
    rv = self.handle_user_exception(e)
  File "c:\users\celia\microblog\venv\lib\site-packages\flask\app.py", line 1718, in handle_user_exception
    reraise(exc_type, exc_value, tb)
  File "c:\users\celia\microblog\venv\lib\site-packages\flask\_compat.py", line 35, in reraise
    raise value
  File "c:\users\celia\microblog\venv\lib\site-packages\flask\app.py", line 1811, in full_dispatch_request
    rv = self.preprocess_request()
  File "c:\users\celia\microblog\venv\lib\site-packages\flask\app.py", line 2087, in preprocess_request
    rv = func()
  File "C:\Users\celia\PIAChatbot\app\main\routes.py", line 17, in before_request
    if current_user.is_authenticated:
  File "c:\users\celia\microblog\venv\lib\site-packages\werkzeug\local.py", line 347, in __getattr__
    return getattr(self._get_current_object(), name)
  File "c:\users\celia\microblog\venv\lib\site-packages\werkzeug\local.py", line 306, in _get_current_object
    return self.__local()
  File "c:\users\celia\microblog\venv\lib\site-packages\flask_login\utils.py", line 26, in <lambda>
    current_user = LocalProxy(lambda: _get_user())
  File "c:\users\celia\microblog\venv\lib\site-packages\flask_login\utils.py", line 335, in _get_user
    current_app.login_manager._load_user()
  File "c:\users\celia\microblog\venv\lib\site-packages\flask_login\login_manager.py", line 359, in _load_user
    return self.reload_user()
  File "c:\users\celia\microblog\venv\lib\site-packages\flask_login\login_manager.py", line 321, in reload_user
    user = self.user_callback(user_id)
  File "C:\Users\celia\PIAChatbot\app\models.py", line 83, in load_user
    return User.query.get(int(id))
  File "c:\users\celia\microblog\venv\lib\site-packages\sqlalchemy\orm\query.py", line 936, in get
    return self._get_impl(ident, loading.load_on_pk_identity)
  File "c:\users\celia\microblog\venv\lib\site-packages\sqlalchemy\orm\query.py", line 1026, in _get_impl
    return db_load_fn(self, primary_key_identity)
  File "c:\users\celia\microblog\venv\lib\site-packages\sqlalchemy\orm\loading.py", line 282, in load_on_pk_identity
    return q.one()
  File "c:\users\celia\microblog\venv\lib\site-packages\sqlalchemy\orm\query.py", line 3039, in one
    ret = self.one_or_none()
  File "c:\users\celia\microblog\venv\lib\site-packages\sqlalchemy\orm\query.py", line 3008, in one_or_none
    ret = list(self)
  File "c:\users\celia\microblog\venv\lib\site-packages\sqlalchemy\orm\query.py", line 3081, in __iter__
    return self._execute_and_instances(context)
  File "c:\users\celia\microblog\venv\lib\site-packages\sqlalchemy\orm\query.py", line 3103, in _execute_and_instances
    querycontext, self._connection_from_session, close_with_result=True
  File "c:\users\celia\microblog\venv\lib\site-packages\sqlalchemy\orm\query.py", line 3111, in _get_bind_args
    mapper=self._bind_mapper(), clause=querycontext.statement, **kw
  File "c:\users\celia\microblog\venv\lib\site-packages\sqlalchemy\orm\query.py", line 3096, in _connection_from_session
    conn = self.session.connection(**kw)
  File "c:\users\celia\microblog\venv\lib\site-packages\sqlalchemy\orm\session.py", line 1120, in connection
    execution_options=execution_options,
  File "c:\users\celia\microblog\venv\lib\site-packages\sqlalchemy\orm\session.py", line 1126, in _connection_for_bind
    engine, execution_options
  File "c:\users\celia\microblog\venv\lib\site-packages\sqlalchemy\orm\session.py", line 424, in _connection_for_bind
    conn = bind.contextual_connect()
  File "c:\users\celia\microblog\venv\lib\site-packages\sqlalchemy\engine\base.py", line 2192, in contextual_connect
    self._wrap_pool_connect(self.pool.connect, None),
  File "c:\users\celia\microblog\venv\lib\site-packages\sqlalchemy\engine\base.py", line 2228, in _wrap_pool_connect
    return fn()
  File "c:\users\celia\microblog\venv\lib\site-packages\sqlalchemy\pool.py", line 425, in connect
    return _ConnectionFairy._checkout(self)
  File "c:\users\celia\microblog\venv\lib\site-packages\sqlalchemy\pool.py", line 822, in _checkout
    fairy = _ConnectionRecord.checkout(pool)
  File "c:\users\celia\microblog\venv\lib\site-packages\sqlalchemy\pool.py", line 554, in checkout
    rec = pool._do_get()
  File "c:\users\celia\microblog\venv\lib\site-packages\sqlalchemy\pool.py", line 1250, in _do_get
    self._dec_overflow()
  File "c:\users\celia\microblog\venv\lib\site-packages\sqlalchemy\util\langhelpers.py", line 67, in __exit__
    compat.reraise(exc_type, exc_value, exc_tb)
  File "c:\users\celia\microblog\venv\lib\site-packages\sqlalchemy\util\compat.py", line 277, in reraise
    raise value
  File "c:\users\celia\microblog\venv\lib\site-packages\sqlalchemy\pool.py", line 1247, in _do_get
    return self._create_connection()
  File "c:\users\celia\microblog\venv\lib\site-packages\sqlalchemy\pool.py", line 370, in _create_connection
    return _ConnectionRecord(self)
  File "c:\users\celia\microblog\venv\lib\site-packages\sqlalchemy\pool.py", line 499, in __init__
    self.__connect(first_connect_check=True)
  File "c:\users\celia\microblog\venv\lib\site-packages\sqlalchemy\pool.py", line 713, in __connect
    pool.dispatch.connect(self.connection, self)
  File "c:\users\celia\microblog\venv\lib\site-packages\sqlalchemy\event\attr.py", line 259, in __call__
    fn(*args, **kw)
  File "c:\users\celia\microblog\venv\lib\site-packages\chatterbot\storage\sql_storage.py", line 43, in set_sqlite_pragma
    dbapi_connection.execute('PRAGMA journal_mode=WAL')
AttributeError: 'Connection' object has no attribute 'execute'
2019-03-03 11:48:39,740 INFO: PIA Chatbot startup [in C:\Users\celia\PIAChatbot\app\__init__.py:73]
