2019-02-27 13:22:43,591 INFO: PIA Chatbot startup [in C:\Users\celia\microblog - Copie\app\__init__.py:74]
2019-02-27 13:22:47,758 ERROR: Exception on /results [GET] [in c:\users\celia\microblog\venv\lib\site-packages\flask\app.py:1761]
Traceback (most recent call last):
  File "c:\users\celia\microblog\venv\lib\site-packages\mysql\connector\connection_cext.py", line 395, in cmd_query
    raw_as_string=raw_as_string)
_mysql_connector.MySQLInterfaceError: No tables used

During handling of the above exception, another exception occurred:

Traceback (most recent call last):
  File "c:\users\celia\microblog\venv\lib\site-packages\flask\app.py", line 2292, in wsgi_app
    response = self.full_dispatch_request()
  File "c:\users\celia\microblog\venv\lib\site-packages\flask\app.py", line 1815, in full_dispatch_request
    rv = self.handle_user_exception(e)
  File "c:\users\celia\microblog\venv\lib\site-packages\flask\app.py", line 1718, in handle_user_exception
    reraise(exc_type, exc_value, tb)
  File "c:\users\celia\microblog\venv\lib\site-packages\flask\_compat.py", line 35, in reraise
    raise value
  File "c:\users\celia\microblog\venv\lib\site-packages\flask\app.py", line 1813, in full_dispatch_request
    rv = self.dispatch_request()
  File "c:\users\celia\microblog\venv\lib\site-packages\flask\app.py", line 1799, in dispatch_request
    return self.view_functions[rule.endpoint](**req.view_args)
  File "C:\Users\celia\microblog - Copie\app\main\routes.py", line 135, in results
    cursor.execute("SELECT *;")
  File "c:\users\celia\microblog\venv\lib\site-packages\mysql\connector\cursor_cext.py", line 266, in execute
    raw_as_string=self._raw_as_string)
  File "c:\users\celia\microblog\venv\lib\site-packages\mysql\connector\connection_cext.py", line 398, in cmd_query
    sqlstate=exc.sqlstate)
mysql.connector.errors.DatabaseError: 1096 (HY000): No tables used
2019-02-27 13:23:26,392 INFO: PIA Chatbot startup [in C:\Users\celia\microblog - Copie\app\__init__.py:74]
2019-02-27 13:23:31,268 ERROR: Exception on /results [GET] [in c:\users\celia\microblog\venv\lib\site-packages\flask\app.py:1761]
Traceback (most recent call last):
  File "c:\users\celia\microblog\venv\lib\site-packages\mysql\connector\connection_cext.py", line 395, in cmd_query
    raw_as_string=raw_as_string)
_mysql_connector.MySQLInterfaceError: Table 'pia.tables' doesn't exist

During handling of the above exception, another exception occurred:

Traceback (most recent call last):
  File "c:\users\celia\microblog\venv\lib\site-packages\flask\app.py", line 2292, in wsgi_app
    response = self.full_dispatch_request()
  File "c:\users\celia\microblog\venv\lib\site-packages\flask\app.py", line 1815, in full_dispatch_request
    rv = self.handle_user_exception(e)
  File "c:\users\celia\microblog\venv\lib\site-packages\flask\app.py", line 1718, in handle_user_exception
    reraise(exc_type, exc_value, tb)
  File "c:\users\celia\microblog\venv\lib\site-packages\flask\_compat.py", line 35, in reraise
    raise value
  File "c:\users\celia\microblog\venv\lib\site-packages\flask\app.py", line 1813, in full_dispatch_request
    rv = self.dispatch_request()
  File "c:\users\celia\microblog\venv\lib\site-packages\flask\app.py", line 1799, in dispatch_request
    return self.view_functions[rule.endpoint](**req.view_args)
  File "C:\Users\celia\microblog - Copie\app\main\routes.py", line 135, in results
    cursor.execute("SELECT * from tables;")
  File "c:\users\celia\microblog\venv\lib\site-packages\mysql\connector\cursor_cext.py", line 266, in execute
    raw_as_string=self._raw_as_string)
  File "c:\users\celia\microblog\venv\lib\site-packages\mysql\connector\connection_cext.py", line 398, in cmd_query
    sqlstate=exc.sqlstate)
mysql.connector.errors.ProgrammingError: 1146 (42S02): Table 'pia.tables' doesn't exist
2019-02-27 13:23:57,544 INFO: PIA Chatbot startup [in C:\Users\celia\microblog - Copie\app\__init__.py:74]
2019-02-27 13:27:30,391 INFO: PIA Chatbot startup [in C:\Users\celia\microblog - Copie\app\__init__.py:74]
2019-02-27 13:27:33,369 INFO: PIA Chatbot startup [in C:\Users\celia\microblog - Copie\app\__init__.py:74]
2019-02-27 13:27:40,951 ERROR: Exception on /results [GET] [in c:\users\celia\microblog\venv\lib\site-packages\flask\app.py:1761]
Traceback (most recent call last):
  File "c:\users\celia\microblog\venv\lib\site-packages\mysql\connector\connection_cext.py", line 395, in cmd_query
    raw_as_string=raw_as_string)
_mysql_connector.MySQLInterfaceError: Table 'pia.tables' doesn't exist

During handling of the above exception, another exception occurred:

Traceback (most recent call last):
  File "c:\users\celia\microblog\venv\lib\site-packages\flask\app.py", line 2292, in wsgi_app
    response = self.full_dispatch_request()
  File "c:\users\celia\microblog\venv\lib\site-packages\flask\app.py", line 1815, in full_dispatch_request
    rv = self.handle_user_exception(e)
  File "c:\users\celia\microblog\venv\lib\site-packages\flask\app.py", line 1718, in handle_user_exception
    reraise(exc_type, exc_value, tb)
  File "c:\users\celia\microblog\venv\lib\site-packages\flask\_compat.py", line 35, in reraise
    raise value
  File "c:\users\celia\microblog\venv\lib\site-packages\flask\app.py", line 1813, in full_dispatch_request
    rv = self.dispatch_request()
  File "c:\users\celia\microblog\venv\lib\site-packages\flask\app.py", line 1799, in dispatch_request
    return self.view_functions[rule.endpoint](**req.view_args)
  File "C:\Users\celia\microblog - Copie\app\main\routes.py", line 135, in results
    cursor.execute("SELECT * from tables;")
  File "c:\users\celia\microblog\venv\lib\site-packages\mysql\connector\cursor_cext.py", line 266, in execute
    raw_as_string=self._raw_as_string)
  File "c:\users\celia\microblog\venv\lib\site-packages\mysql\connector\connection_cext.py", line 398, in cmd_query
    sqlstate=exc.sqlstate)
mysql.connector.errors.ProgrammingError: 1146 (42S02): Table 'pia.tables' doesn't exist
2019-02-27 13:28:38,168 INFO: PIA Chatbot startup [in C:\Users\celia\microblog - Copie\app\__init__.py:74]
2019-02-27 13:28:43,102 ERROR: Exception on /results [GET] [in c:\users\celia\microblog\venv\lib\site-packages\flask\app.py:1761]
Traceback (most recent call last):
  File "c:\users\celia\microblog\venv\lib\site-packages\flask\app.py", line 2292, in wsgi_app
    response = self.full_dispatch_request()
  File "c:\users\celia\microblog\venv\lib\site-packages\flask\app.py", line 1815, in full_dispatch_request
    rv = self.handle_user_exception(e)
  File "c:\users\celia\microblog\venv\lib\site-packages\flask\app.py", line 1718, in handle_user_exception
    reraise(exc_type, exc_value, tb)
  File "c:\users\celia\microblog\venv\lib\site-packages\flask\_compat.py", line 35, in reraise
    raise value
  File "c:\users\celia\microblog\venv\lib\site-packages\flask\app.py", line 1813, in full_dispatch_request
    rv = self.dispatch_request()
  File "c:\users\celia\microblog\venv\lib\site-packages\flask\app.py", line 1799, in dispatch_request
    return self.view_functions[rule.endpoint](**req.view_args)
  File "C:\Users\celia\microblog - Copie\app\main\routes.py", line 137, in results
    return render_template('results.html',value=result)#value=db.metadata.sorted_tables)
NameError: name 'result' is not defined
2019-02-27 13:29:07,578 INFO: PIA Chatbot startup [in C:\Users\celia\microblog - Copie\app\__init__.py:74]
2019-02-27 13:31:52,355 INFO: PIA Chatbot startup [in C:\Users\celia\microblog - Copie\app\__init__.py:74]
2019-02-27 13:34:00,625 INFO: PIA Chatbot startup [in C:\Users\celia\microblog - Copie\app\__init__.py:74]
2019-02-27 13:34:02,204 INFO: PIA Chatbot startup [in C:\Users\celia\microblog - Copie\app\__init__.py:74]
2019-02-27 13:34:04,637 INFO: PIA Chatbot startup [in C:\Users\celia\microblog - Copie\app\__init__.py:74]
2019-02-27 13:34:32,395 INFO: PIA Chatbot startup [in C:\Users\celia\microblog - Copie\app\__init__.py:74]
2019-02-27 13:35:33,817 INFO: PIA Chatbot startup [in C:\Users\celia\microblog - Copie\app\__init__.py:74]
2019-02-27 13:38:56,500 INFO: PIA Chatbot startup [in C:\Users\celia\microblog - Copie\app\__init__.py:74]
2019-02-27 13:41:28,298 INFO: PIA Chatbot startup [in C:\Users\celia\microblog - Copie\app\__init__.py:74]
2019-02-27 13:41:49,712 INFO: PIA Chatbot startup [in C:\Users\celia\microblog - Copie\app\__init__.py:74]
