2019-02-26 22:46:44,773 ERROR: Exception on /database [GET] [in c:\users\celia\microblog\venv\lib\site-packages\flask\app.py:1761]
Traceback (most recent call last):
  File "c:\users\celia\microblog\venv\lib\site-packages\flask\app.py", line 2292, in wsgi_app
    response = self.full_dispatch_request()
  File "c:\users\celia\microblog\venv\lib\site-packages\flask\app.py", line 1815, in full_dispatch_request
    rv = self.handle_user_exception(e)
  File "c:\users\celia\microblog\venv\lib\site-packages\flask\app.py", line 1718, in handle_user_exception
    reraise(exc_type, exc_value, tb)
  File "c:\users\celia\microblog\venv\lib\site-packages\flask\_compat.py", line 35, in reraise
    raise value
  File "c:\users\celia\microblog\venv\lib\site-packages\flask\app.py", line 1813, in full_dispatch_request
    rv = self.dispatch_request()
  File "c:\users\celia\microblog\venv\lib\site-packages\flask\app.py", line 1799, in dispatch_request
    return self.view_functions[rule.endpoint](**req.view_args)
  File "C:\Users\celia\microblog\app\main\routes.py", line 129, in display_database
    return redirect(url_for('main.results'))
  File "c:\users\celia\microblog\venv\lib\site-packages\flask\helpers.py", line 356, in url_for
    return appctx.app.handle_url_build_error(error, endpoint, values)
  File "c:\users\celia\microblog\venv\lib\site-packages\flask\app.py", line 2061, in handle_url_build_error
    reraise(exc_type, exc_value, tb)
  File "c:\users\celia\microblog\venv\lib\site-packages\flask\_compat.py", line 35, in reraise
    raise value
  File "c:\users\celia\microblog\venv\lib\site-packages\flask\helpers.py", line 345, in url_for
    force_external=external)
  File "c:\users\celia\microblog\venv\lib\site-packages\werkzeug\routing.py", line 1776, in build
    raise BuildError(endpoint, values, method, self)
werkzeug.routing.BuildError: Could not build url for endpoint 'main.results'. Did you mean 'main.user' instead?
2019-02-26 22:48:17,702 INFO: PIA Chatbot startup [in C:\Users\celia\microblog\app\__init__.py:74]
2019-02-26 22:48:21,345 ERROR: Exception on /database [GET] [in c:\users\celia\microblog\venv\lib\site-packages\flask\app.py:1761]
Traceback (most recent call last):
  File "c:\users\celia\microblog\venv\lib\site-packages\flask\app.py", line 2292, in wsgi_app
    response = self.full_dispatch_request()
  File "c:\users\celia\microblog\venv\lib\site-packages\flask\app.py", line 1815, in full_dispatch_request
    rv = self.handle_user_exception(e)
  File "c:\users\celia\microblog\venv\lib\site-packages\flask\app.py", line 1718, in handle_user_exception
    reraise(exc_type, exc_value, tb)
  File "c:\users\celia\microblog\venv\lib\site-packages\flask\_compat.py", line 35, in reraise
    raise value
  File "c:\users\celia\microblog\venv\lib\site-packages\flask\app.py", line 1813, in full_dispatch_request
    rv = self.dispatch_request()
  File "c:\users\celia\microblog\venv\lib\site-packages\flask\app.py", line 1799, in dispatch_request
    return self.view_functions[rule.endpoint](**req.view_args)
  File "C:\Users\celia\microblog\app\main\routes.py", line 129, in display_database
    return redirect(url_for('main.results'))
  File "c:\users\celia\microblog\venv\lib\site-packages\flask\helpers.py", line 356, in url_for
    return appctx.app.handle_url_build_error(error, endpoint, values)
  File "c:\users\celia\microblog\venv\lib\site-packages\flask\app.py", line 2061, in handle_url_build_error
    reraise(exc_type, exc_value, tb)
  File "c:\users\celia\microblog\venv\lib\site-packages\flask\_compat.py", line 35, in reraise
    raise value
  File "c:\users\celia\microblog\venv\lib\site-packages\flask\helpers.py", line 345, in url_for
    force_external=external)
  File "c:\users\celia\microblog\venv\lib\site-packages\werkzeug\routing.py", line 1776, in build
    raise BuildError(endpoint, values, method, self)
werkzeug.routing.BuildError: Could not build url for endpoint 'main.results'. Did you mean 'main.user' instead?
2019-02-26 22:53:51,073 INFO: PIA Chatbot startup [in C:\Users\celia\microblog\app\__init__.py:74]
2019-02-26 22:54:30,322 INFO: PIA Chatbot startup [in C:\Users\celia\microblog\app\__init__.py:74]
2019-02-26 22:57:40,276 INFO: PIA Chatbot startup [in C:\Users\celia\microblog\app\__init__.py:74]
2019-02-26 23:06:00,370 INFO: PIA Chatbot startup [in C:\Users\celia\microblog\app\__init__.py:74]
2019-02-26 23:06:02,831 ERROR: Exception on /database [GET] [in c:\users\celia\microblog\venv\lib\site-packages\flask\app.py:1761]
Traceback (most recent call last):
  File "c:\users\celia\microblog\venv\lib\site-packages\flask\app.py", line 2292, in wsgi_app
    response = self.full_dispatch_request()
  File "c:\users\celia\microblog\venv\lib\site-packages\flask\app.py", line 1815, in full_dispatch_request
    rv = self.handle_user_exception(e)
  File "c:\users\celia\microblog\venv\lib\site-packages\flask\app.py", line 1718, in handle_user_exception
    reraise(exc_type, exc_value, tb)
  File "c:\users\celia\microblog\venv\lib\site-packages\flask\_compat.py", line 35, in reraise
    raise value
  File "c:\users\celia\microblog\venv\lib\site-packages\flask\app.py", line 1813, in full_dispatch_request
    rv = self.dispatch_request()
  File "c:\users\celia\microblog\venv\lib\site-packages\flask\app.py", line 1799, in dispatch_request
    return self.view_functions[rule.endpoint](**req.view_args)
  File "C:\Users\celia\microblog\app\main\routes.py", line 129, in display_database
    return render_template('results.html', title='BDD',table=table)
NameError: name 'table' is not defined
2019-02-26 23:08:10,342 INFO: PIA Chatbot startup [in C:\Users\celia\microblog\app\__init__.py:74]
2019-02-27 09:01:38,782 INFO: PIA Chatbot startup [in C:\Users\celia\microblog\app\__init__.py:74]
2019-02-27 09:03:23,469 INFO: PIA Chatbot startup [in C:\Users\celia\microblog\app\__init__.py:74]
2019-02-27 09:07:09,920 INFO: PIA Chatbot startup [in C:\Users\celia\microblog\app\__init__.py:74]
2019-02-27 09:17:43,159 INFO: PIA Chatbot startup [in C:\Users\celia\microblog\app\__init__.py:74]
2019-02-27 09:21:11,295 INFO: PIA Chatbot startup [in C:\Users\celia\microblog\app\__init__.py:74]
2019-02-27 09:30:01,143 INFO: PIA Chatbot startup [in C:\Users\celia\microblog\app\__init__.py:74]
2019-02-27 09:30:14,583 INFO: PIA Chatbot startup [in C:\Users\celia\microblog\app\__init__.py:74]
2019-02-27 09:34:02,849 INFO: PIA Chatbot startup [in C:\Users\celia\microblog\app\__init__.py:74]
2019-02-27 09:34:05,674 ERROR: Exception on /database [GET] [in c:\users\celia\microblog\venv\lib\site-packages\flask\app.py:1761]
Traceback (most recent call last):
  File "c:\users\celia\microblog\venv\lib\site-packages\flask\app.py", line 2292, in wsgi_app
    response = self.full_dispatch_request()
  File "c:\users\celia\microblog\venv\lib\site-packages\flask\app.py", line 1815, in full_dispatch_request
    rv = self.handle_user_exception(e)
  File "c:\users\celia\microblog\venv\lib\site-packages\flask\app.py", line 1718, in handle_user_exception
    reraise(exc_type, exc_value, tb)
  File "c:\users\celia\microblog\venv\lib\site-packages\flask\_compat.py", line 35, in reraise
    raise value
  File "c:\users\celia\microblog\venv\lib\site-packages\flask\app.py", line 1813, in full_dispatch_request
    rv = self.dispatch_request()
  File "c:\users\celia\microblog\venv\lib\site-packages\flask\app.py", line 1799, in dispatch_request
    return self.view_functions[rule.endpoint](**req.view_args)
  File "C:\Users\celia\microblog\app\main\routes.py", line 129, in display_database
    return render_template('results.html', title='BDD')
  File "c:\users\celia\microblog\venv\lib\site-packages\flask\templating.py", line 135, in render_template
    context, ctx.app)
  File "c:\users\celia\microblog\venv\lib\site-packages\flask\templating.py", line 117, in _render
    rv = template.render(context)
  File "c:\users\celia\microblog\venv\lib\site-packages\jinja2\asyncsupport.py", line 76, in render
    return original_render(self, *args, **kwargs)
  File "c:\users\celia\microblog\venv\lib\site-packages\jinja2\environment.py", line 1008, in render
    return self.environment.handle_exception(exc_info, True)
  File "c:\users\celia\microblog\venv\lib\site-packages\jinja2\environment.py", line 780, in handle_exception
    reraise(exc_type, exc_value, tb)
  File "c:\users\celia\microblog\venv\lib\site-packages\jinja2\_compat.py", line 37, in reraise
    raise value.with_traceback(tb)
  File "C:\Users\celia\microblog\app\templates\results.html", line 1, in top-level template code
    {% extends "base.html" %}
  File "C:\Users\celia\microblog\app\templates\base.html", line 1, in top-level template code
    {% extends 'bootstrap/base.html' %}
  File "c:\users\celia\microblog\venv\lib\site-packages\flask_bootstrap\templates\bootstrap\base.html", line 1, in top-level template code
    {% block doc -%}
  File "c:\users\celia\microblog\venv\lib\site-packages\flask_bootstrap\templates\bootstrap\base.html", line 4, in block "doc"
    {%- block html %}
  File "c:\users\celia\microblog\venv\lib\site-packages\flask_bootstrap\templates\bootstrap\base.html", line 20, in block "html"
    {% block body -%}
  File "c:\users\celia\microblog\venv\lib\site-packages\flask_bootstrap\templates\bootstrap\base.html", line 23, in block "body"
    {% block content -%}
  File "C:\Users\celia\microblog\app\templates\base.html", line 48, in block "content"
    {% block app_content %}{% endblock %}
  File "C:\Users\celia\microblog\app\templates\results.html", line 10, in block "app_content"
    {{ db.metadata.sorted_tables }}
  File "c:\users\celia\microblog\venv\lib\site-packages\jinja2\environment.py", line 430, in getattr
    return getattr(obj, attribute)
jinja2.exceptions.UndefinedError: 'db' is undefined
2019-02-27 09:35:18,059 INFO: PIA Chatbot startup [in C:\Users\celia\microblog\app\__init__.py:74]
2019-02-27 09:36:34,299 INFO: PIA Chatbot startup [in C:\Users\celia\microblog\app\__init__.py:74]
