2019-02-27 10:53:55,428 ERROR: Exception on /database [GET] [in c:\users\celia\microblog\venv\lib\site-packages\flask\app.py:1761]
Traceback (most recent call last):
  File "c:\users\celia\microblog\venv\lib\site-packages\sqlalchemy\util\_collections.py", line 1005, in __call__
    return self.registry[key]
KeyError: 9676

During handling of the above exception, another exception occurred:

Traceback (most recent call last):
  File "c:\users\celia\microblog\venv\lib\site-packages\flask\app.py", line 2292, in wsgi_app
    response = self.full_dispatch_request()
  File "c:\users\celia\microblog\venv\lib\site-packages\flask\app.py", line 1815, in full_dispatch_request
    rv = self.handle_user_exception(e)
  File "c:\users\celia\microblog\venv\lib\site-packages\flask\app.py", line 1718, in handle_user_exception
    reraise(exc_type, exc_value, tb)
  File "c:\users\celia\microblog\venv\lib\site-packages\flask\_compat.py", line 35, in reraise
    raise value
  File "c:\users\celia\microblog\venv\lib\site-packages\flask\app.py", line 1811, in full_dispatch_request
    rv = self.preprocess_request()
  File "c:\users\celia\microblog\venv\lib\site-packages\flask\app.py", line 2087, in preprocess_request
    rv = func()
  File "C:\Users\celia\microblog - Copie\app\main\routes.py", line 17, in before_request
    if current_user.is_authenticated:
  File "c:\users\celia\microblog\venv\lib\site-packages\werkzeug\local.py", line 347, in __getattr__
    return getattr(self._get_current_object(), name)
  File "c:\users\celia\microblog\venv\lib\site-packages\werkzeug\local.py", line 306, in _get_current_object
    return self.__local()
  File "c:\users\celia\microblog\venv\lib\site-packages\flask_login\utils.py", line 26, in <lambda>
    current_user = LocalProxy(lambda: _get_user())
  File "c:\users\celia\microblog\venv\lib\site-packages\flask_login\utils.py", line 335, in _get_user
    current_app.login_manager._load_user()
  File "c:\users\celia\microblog\venv\lib\site-packages\flask_login\login_manager.py", line 359, in _load_user
    return self.reload_user()
  File "c:\users\celia\microblog\venv\lib\site-packages\flask_login\login_manager.py", line 321, in reload_user
    user = self.user_callback(user_id)
  File "C:\Users\celia\microblog - Copie\app\models.py", line 83, in load_user
    return User.query.get(int(id))
  File "c:\users\celia\microblog\venv\lib\site-packages\flask_sqlalchemy\__init__.py", line 514, in __get__
    return type.query_class(mapper, session=self.sa.session())
  File "c:\users\celia\microblog\venv\lib\site-packages\sqlalchemy\orm\scoping.py", line 78, in __call__
    return self.registry()
  File "c:\users\celia\microblog\venv\lib\site-packages\sqlalchemy\util\_collections.py", line 1007, in __call__
    return self.registry.setdefault(key, self.createfunc())
  File "c:\users\celia\microblog\venv\lib\site-packages\sqlalchemy\orm\session.py", line 3171, in __call__
    return self.class_(**local_kw)
  File "c:\users\celia\microblog\venv\lib\site-packages\flask_sqlalchemy\__init__.py", line 143, in __init__
    bind = options.pop('bind', None) or db.engine
  File "c:\users\celia\microblog\venv\lib\site-packages\flask_sqlalchemy\__init__.py", line 877, in engine
    return self.get_engine()
  File "c:\users\celia\microblog\venv\lib\site-packages\flask_sqlalchemy\__init__.py", line 896, in get_engine
    return connector.get_engine()
  File "c:\users\celia\microblog\venv\lib\site-packages\flask_sqlalchemy\__init__.py", line 559, in get_engine
    self._engine = rv = sqlalchemy.create_engine(info, **options)
  File "c:\users\celia\microblog\venv\lib\site-packages\sqlalchemy\engine\__init__.py", line 431, in create_engine
    return strategy.create(*args, **kwargs)
  File "c:\users\celia\microblog\venv\lib\site-packages\sqlalchemy\engine\strategies.py", line 87, in create
    dbapi = dialect_cls.dbapi(**dbapi_args)
  File "c:\users\celia\microblog\venv\lib\site-packages\sqlalchemy\dialects\mysql\mysqldb.py", line 104, in dbapi
    return __import__("MySQLdb")
ModuleNotFoundError: No module named 'MySQLdb'
2019-02-27 10:57:32,916 INFO: PIA Chatbot startup [in C:\Users\celia\microblog - Copie\app\__init__.py:74]
